When trying on Debian 12, get this error:-

python manage.py runserver
Traceback (most recent call last):
  File "/home/afmy/desktop/django-income-expense-website/expenseswebsite/manage.py", line 22, in <module>
    main()
  File "/home/afmy/desktop/django-income-expense-website/expenseswebsite/manage.py", line 18, in main
    execute_from_command_line(sys.argv)
  File "/home/afmy/.local/share/virtualenvs/django-income-expense-website-t30zqxI0/lib/python3.11/site-packages/django/core/management/__init__.py", line 442, in execute_from_command_line
    utility.execute()
  File "/home/afmy/.local/share/virtualenvs/django-income-expense-website-t30zqxI0/lib/python3.11/site-packages/django/core/management/__init__.py", line 382, in execute
    settings.INSTALLED_APPS
  File "/home/afmy/.local/share/virtualenvs/django-income-expense-website-t30zqxI0/lib/python3.11/site-packages/django/conf/__init__.py", line 89, in __getattr__
    self._setup(name)
  File "/home/afmy/.local/share/virtualenvs/django-income-expense-website-t30zqxI0/lib/python3.11/site-packages/django/conf/__init__.py", line 76, in _setup
    self._wrapped = Settings(settings_module)
                    ^^^^^^^^^^^^^^^^^^^^^^^^^
  File "/home/afmy/.local/share/virtualenvs/django-income-expense-website-t30zqxI0/lib/python3.11/site-packages/django/conf/__init__.py", line 190, in __init__
    mod = importlib.import_module(self.SETTINGS_MODULE)
          ^^^^^^^^^^^^^^^^^^^^^^^^^^^^^^^^^^^^^^^^^^^^^
  File "/usr/lib/python3.11/importlib/__init__.py", line 126, in import_module
    return _bootstrap._gcd_import(name[level:], package, level)
           ^^^^^^^^^^^^^^^^^^^^^^^^^^^^^^^^^^^^^^^^^^^^^^^^^^^^
  File "<frozen importlib._bootstrap>", line 1206, in _gcd_import
  File "<frozen importlib._bootstrap>", line 1178, in _find_and_load
  File "<frozen importlib._bootstrap>", line 1149, in _find_and_load_unlocked
  File "<frozen importlib._bootstrap>", line 690, in _load_unlocked
  File "<frozen importlib._bootstrap_external>", line 940, in exec_module
  File "<frozen importlib._bootstrap>", line 241, in _call_with_frames_removed
  File "/home/afmy/desktop/django-income-expense-website/expenseswebsite/expenseswebsite/settings.py", line 14, in <module>
    django_on_heroku.settings(locals())
  File "/home/afmy/.local/share/virtualenvs/django-income-expense-website-t30zqxI0/lib/python3.11/site-packages/django_on_heroku/core.py", line 110, in settings
    config['STATIC_ROOT'] = os.path.join(config['BASE_DIR'], 'staticfiles')
                                         ~~~~~~^^^^^^^^^^^^
KeyError: 'BASE_DIR'
